{
 "cells": [
  {
   "cell_type": "code",
   "execution_count": 1,
   "id": "b2f813fa-2acc-4404-84a7-9df18ca19ff2",
   "metadata": {},
   "outputs": [
    {
     "ename": "SyntaxError",
     "evalue": "unmatched ')' (4001347657.py, line 10)",
     "output_type": "error",
     "traceback": [
      "\u001b[0;36m  Cell \u001b[0;32mIn[1], line 10\u001b[0;36m\u001b[0m\n\u001b[0;31m    1). try to open a file(for reading) that does not  exist(FileNotFoundError)\u001b[0m\n\u001b[0m     ^\u001b[0m\n\u001b[0;31mSyntaxError\u001b[0m\u001b[0;31m:\u001b[0m unmatched ')'\n"
     ]
    }
   ],
   "source": [
    "Question: Whhat is exception in python? write the difference between exceptions and syntax errors.\n",
    "Answer: \n",
    "PYTHON EXCEPTIONS: an exception is an unexpected event that occurs during program execution. For example,\n",
    "divide_by_zero = 7/0\n",
    "the above code causes an exeception as it is not possible to divide a number by 0.\n",
    "\n",
    "python logical errors(exceptions):\n",
    "    errors that occur at runtime(after passing the syntax test) are called exceptions or logical errors.\n",
    "    For instance, they occur when we\n",
    "1). try to open a file(for reading) that does not  exist(FileNotFoundError)\n",
    "2). try to divide a number by zero( ZeroDivisionError)\n",
    "3). try to import a module that does not exist(ImportError) and so on.\n",
    "whenever these types of runtime error occur, python creates an exception object.\n",
    "\n",
    "Differnce between exceptions and syntax errors:\n",
    "    \n",
    "    Errors are the problem due to which the program will stop the execution. on the other hand, exceptions are raised when some inernal events occur will changes the normal flow\n",
    "of the program.\n",
    "Two types of error occurs in python.\n",
    "1). syntax error\n",
    "2). logical error(Exceptions)\n",
    "\n",
    "syntax error: when the proper syntax of the languaes is not followed then a syntax error is thrown.\n",
    "Example:\n",
    "amount = 10000\n",
    "if(amount>2999)\n",
    "print(\"you are eligible to purchase books\")\n",
    "it returns a syntax error message because after the if statement a colon: is missing. we can fix this by writing the correct syntax.\n",
    "\n",
    "\n",
    "Exception errors:\n",
    "    when in the runtime an error that occurs after passing the syntax test is called exception or logical type.\n",
    "Example: when we divide any number by zero then ZeroDivisonError exception is raised, or when we import a module that does not exist then ImpotError raised.\n",
    "\n",
    "\n"
   ]
  },
  {
   "cell_type": "code",
   "execution_count": null,
   "id": "c6b4848f-19b9-4ba5-88b9-79fb9764a262",
   "metadata": {},
   "outputs": [],
   "source": [
    "Question: What happens when an exception is not handled? explain with an example.\n",
    "\n",
    "Answer: if the exception not handled, they will terminate the program and produce a traceback.\n",
    "\n",
    "Eample: Exception Handling Using try... except\n",
    "try:\n",
    "    numerator = 10\n",
    "    denominator= 0\n",
    "    \n",
    "    result = numerator/denominator\n",
    "    \n",
    "    print(result)\n",
    "except:\n",
    "    print(\"error: denominator cannot be 0.\")\n",
    "#output: Error: Denominator cannot be 0.\n",
    "\n",
    "in this example, we are trying to divide a number by 0.\n",
    "here, this code generates an exception.\n",
    "\n",
    "To handle the exception, we have put the code,\n",
    "[result = numerator/denominator] inside the [try] block. now when an exception occurs, the rest of the code inside the [try] block is skipped.\n",
    "the [except] block cathces the exception and statements inside the [except] block are executed."
   ]
  },
  {
   "cell_type": "code",
   "execution_count": null,
   "id": "fd6cb40f-7208-490e-8af0-b199d62e75da",
   "metadata": {},
   "outputs": [],
   "source": [
    "Question: Which python statements are used to catch and handle exceptions? Explain with an example.\n",
    "Answer: the try and except block in python is used to catch and handle exceptions. \n",
    "the following function can help you understand the try and except block:\n",
    "Let's take a simple example below:\n",
    "\n",
    "print(3/0)\n",
    "#the code will generate an error message while the program terminates:\n",
    "ZeroDivisonError: division by  zero\n",
    "\n",
    "#the line of code that throws the exception can be handled as follows:\n",
    "\n",
    "try:\n",
    "    print(3/0)\n",
    "except ZeroDivisionError:\n",
    "    print(\"cannot divide number by zero\")\n",
    "    \n",
    "In the example above, we place the first print statement within [try] block. The piece of code within this block will raise an exception, because dividing a number by zero has no\n",
    "meaning. the try and except blocks are often used together for handling exceptions in pthon."
   ]
  },
  {
   "cell_type": "code",
   "execution_count": null,
   "id": "652dff05-95be-44dc-9854-ae4e70317e68",
   "metadata": {},
   "outputs": [],
   "source": [
    "Question: Explain with an example:\n",
    "a. try and else\n",
    "b. finally\n",
    "c. raise\n",
    "\n",
    "Answer: \n",
    "try block: The block is used when the code is needed to check for some errors. if there are no errors in the code then the code unde the try block will get executed.\n",
    "\n",
    "except block: whenever there is some error in the try block preceding the except block, the code under except block executes.\n",
    "\n",
    "SYNTAX: \n",
    "try:\n",
    "    #some code to try\n",
    "except:\n",
    "    #if an error is present in\n",
    "    #the code try, then\n",
    "    #code under except executes\n",
    "    \n",
    "else block: an else block can also be added on thr try-except block and it should be present after all the the except blocks. if the try block suceesfully does not raise an \n",
    "exception then code enters into the else the block.\n",
    "\n",
    "SYNTAX: \n",
    "try:\n",
    "    #some code to check error\n",
    "except:\n",
    "    #if an error in the\n",
    "    #try block then this block runs\n",
    "else:\n",
    "    #executes this block if \n",
    "    #there is no exception in the try block\n",
    "    \n",
    "finally keyword:\n",
    "In python, we use the final keyword, which is executed always even if the exception is not handled and the try-except is terminated. it is executed after thr try-except\n",
    "block.\n",
    "\n",
    "SYNTAX:\n",
    "try:\n",
    "    #some code for error\n",
    "except:\n",
    "    #if an error in the\n",
    "    #try block then execute this block\n",
    "else:\n",
    "    #if no exception then executes this\n",
    "finally:\n",
    "    #this code always executed after the try-except\n",
    "    \n",
    "Raise keyword:\n",
    "    the raise keyword is used to raise an exception.\n",
    "    you can define what kind of error to raise, and the text to print to the user.\n",
    "    \n",
    "Example:\n",
    "Raise a TypeError if x is not an integer.\n",
    "\n",
    "x = \"hello\"\n",
    "if not type(x) is int:\n",
    "    raise TypeError(\"only integers are allowed\")"
   ]
  },
  {
   "cell_type": "code",
   "execution_count": null,
   "id": "aa4d9759-d1aa-4fd3-b0d9-9c3e0897684e",
   "metadata": {},
   "outputs": [],
   "source": [
    "Question: What are custom exceptions in python? why do we need custom exceptions? explain with an example.\n",
    "Answer: \n",
    "Defining custom exceptions:\n",
    "Like standard exception classes, custom exceptions are also classes. hence, you can add functionality to the custom exception classes like:\n",
    "~ Adding attribute and properties.\n",
    "~adding methods e.g., log the exception, format the output, etc.\n",
    "\n",
    "Why do we need exceptions:\n",
    "custom exceptions provide you the flexibility to add attribute and methods that are not part of a standard exception. these can store additional information.\n",
    "\n",
    "Example:\n",
    "class NegativeError(exception):\n",
    "    def __init__(self, data):\n",
    "        self.data = data\n",
    "try:\n",
    "    x = int(input(\"Enter a number between positive integer:\"))\n",
    "    if x<0:\n",
    "        raise NegativeError(x)\n",
    "except NegativeError as e:\n",
    "    print(\"you provided {}. please provide positive integer values only\". format (e))"
   ]
  },
  {
   "cell_type": "code",
   "execution_count": null,
   "id": "bf43ab44-61b3-4c97-aaf7-7e2b497cfaf1",
   "metadata": {},
   "outputs": [],
   "source": [
    "Question: create a custom exception class. use this class to handle an exception.\n",
    "Answer: \n",
    "class FahrenheitError(Exception):\n",
    "    min_f =32\n",
    "    max_f = 212\n",
    "    \n",
    "    def __init__(self, f, *args):\n",
    "        super().__init__9args)\n",
    "        self.f = f\n",
    "    \n",
    "    def __str__(self):\n",
    "        return f' The {self.f} is not in a valid range{self.min_f, self.max_f}'"
   ]
  },
  {
   "cell_type": "code",
   "execution_count": null,
   "id": "01b3306a-32d3-4d91-afa7-89ccd984b233",
   "metadata": {},
   "outputs": [],
   "source": []
  },
  {
   "cell_type": "code",
   "execution_count": null,
   "id": "9fa50456-4a62-4742-b2d4-d9a59ec593b6",
   "metadata": {},
   "outputs": [],
   "source": []
  },
  {
   "cell_type": "code",
   "execution_count": null,
   "id": "27297dde-710d-4221-91ad-1e4a01f40c53",
   "metadata": {},
   "outputs": [],
   "source": []
  }
 ],
 "metadata": {
  "kernelspec": {
   "display_name": "Python 3 (ipykernel)",
   "language": "python",
   "name": "python3"
  },
  "language_info": {
   "codemirror_mode": {
    "name": "ipython",
    "version": 3
   },
   "file_extension": ".py",
   "mimetype": "text/x-python",
   "name": "python",
   "nbconvert_exporter": "python",
   "pygments_lexer": "ipython3",
   "version": "3.10.8"
  }
 },
 "nbformat": 4,
 "nbformat_minor": 5
}
